Workbook

Sheet Release_Notice
A1: DATE | B1: Revision | C1: UPDATE SHEET | D1: Reason of change | E1: SIGN
A2: 45182 | B2: 0 | C2: ALL SHEET | D2: Initial Release | E2: Sophia
A3: 45201 | B3: 1 | C3: DELTA_PN | D3: Add new SXM PN:692-2G510-0210-0R2 | E3: Sophia
A4: 45202 | B4: 1.1 | C4: DELTA_PN | D4: Add below new PN: 935-23587-0001-000 935-23587-0001-200 935-23587-0011-200 935-23587-0011-201 935-23587-A800-000 935-23587-0300-000 935-23587-0300-200 935-23587-0301-000 | E4: Sophia
A5: 45205 | B5: 1.2 | C5: LUNAGPU_PN LUNACPU_PN | D5: Add below for Luna Wistron PN Build-as WPN | E5: Sophia
A6: 45214 | B6: 1.3 | C6: LUNAGPU_PN | D6: Add 675-23587-1000-5R6 | E6: Sophia
A7: 45218 | B7: 1.4 | C7: VULCAN_PN | D7: Add Vulcan | E7: Sophia
A8: 45233 | B8: 1.5 | C8: VULCAN_PN | D8: Add Vulcan information | E8: Sophia
A9: 45236 | B9: 1.6 | C9: VULCAN_PN | D9: Add HMC PN | E9: Sophia
A10: 45260 | B10: 1.7 | C10: DELTA_PN | D10: Add 935-23587-0000-204 | E10: Sophia
A11: 45288 | B11: 1.8 | C11: DELTA_PN | D11: Modify the SXM PN of 935-23587-0000-2R0/935-23587-A800-2R1/935-23587-0300-2R0 | E11: Sophia
A12: 45299 | B12: 1.9 | C12: DELTA_PN LUNAGPU_PN REDSTONE_PN VIKINGCPU_PN | D12: Diag Version | E12: Sophia
A13: 45302 | B13: 2 | C13: VULCAN_PN REDSTONE_PN | D13: Add PN | E13: Sophia
... A56: 45735 | B56: 6.3 | C56: VULCAN_PN(H200) VULCAN_PN(H20) | D56: Update SXM PN | E56: Sophia

Sheet DELTA_PN
A1: Customer | B1: Possible return Part Number | C1: 40G/80G | D1: Build-As | E1: SXM PN | F1: B02/B04/D01 | G1: Sorting Diag | H1: Online Diag | I1: Diag Version | J1: Diag Version Change Summary | K1: Diag Release Date | L1: Diag Varify Date | M1: ECO # | N1: BB PN | O1: Serviceme | P1: Serviceme big category | Q1: LABEL PLAN | R1: LABEL FILE | S1: Remarks
A2: Google | B2: 935-23587-6300-000 | C2: 40G | D2: 935-23587-6300-0R3 | E2: 692-2G506-0200-0R6 692-2G510-0200-0R0 | F2: B04 | G2: verified | H2: verified | I2: MODS_VER:618-23587-XXXX-MOD-40200 FLA_VER:618-23587-XXXX-FLA-39754 FLC_VER:618-23587-0000-FLC-40602 FTT_VER:618-23587-XXXX-FTT-37526 SKU_VER;618-23587-0000-SKU-40277 | K2: 45701 | L2: 45701 | N2: 699-24612-1000-5R1 699-24612-1000-5R2 | O2: 699-24612-1000-5R1 699-24612-1000-5R2 | Q2: 935-23587-xxxx-xxx label plan 20230522.xlsx [935-23587-6300-0R3 ] | R2: Delta 6300-0R3 | S2: DOA Gold BB, Using Pilot unit for validation Waiting for loopback card
B3: 935-23587-6300-001 | C3: 40G | T3: Legend
B4: 935-23587-6300-002 | C4: 40G | T4: Ready | U4: Diag available
B5: 935-23587-6300-003 | C5: 40G | T5: Verified | U5: Diag available &Verified
B6: 935-23587-6300-0R2 | C6: 40G | T6: Not available | U6: Not avialble
B7: 935-23587-6300-0R3 | C7: 40G
B8: 935-23587-6300-201 | C8: 80G | D8: 935-23587-6300-2R1 | E8: 692-2G506-0210-0R6 692-2G510-0210-0R3 692-2G510-0210-0R2 | F8: B04 | G8: verified | H8: verified | I8: MODS_VER:618-23587-XXXX-MOD-40200 FLA_VER:618-23587-XXXX-FLA-39754 FLC_VER:618-23587-0000-FLC-40602 FTT_VER:618-23587-XXXX-FTT-37526 DCC_VER:618-23587-XXXX-DCC-37528 SKU_VER:618-23587-XXXX-SKU-40539 | K8: 45573 | L8: 45573 | N8: 699-24612-1000-5R2 | O8: =VLOOKUP(N8,'Item Master 91223'!C:C,1,0) -> 699-24612-1000-5R2 | P8: =VLOOKUP(N8,'Item Master 91223'!C:L,10,0) -> BG | Q8: 935-23587-0000-xxx label plan v13 082224.xlsx [935-23587-6300-2R1_Google_506] | R8: Delta 6300-2R1 | S8: No Gold BB, Using Pilot unit for validation Waiting for loopback card
B9: 935-23587-6300-204 | C9: 80G | D9: 935-23587-6300-204 | E9: 692-2G510-0210-002 692-2G510-0210-003 692-2G506-0210-006 692-2G506-0210-007 692-2G506-0210-008 692-2G506-0210-009 | F9: D01 | N9: 699-24612-1000-900
A10: Generic | B10: 935-23587-0000-000 | C10: 40G | D10: 935-23587-0000-0R0 | E10: 692-2G506-0200-0R6 | F10: B02 | G10: verified | H10: verified | I10: MODS_VER:618-23587-XXXX-MOD-40200 FLA_VER:618-23587-XXXX-FLA-39754 FLC_VER:618-23587-0000-FLC-39071 FTT_VER:618-23587-XXXX-FTT-37526 DCC_Ver:618-23587-XXXX-DCC-37528 SKU_VER:618-23587-0000-SKU-40116 | K10: 45499 | L10: 45499 | N10: 699-24612-1000-3R6 | O10: =VLOOKUP(N10,'Item Master 91223'!C:C,1,0) -> 699-24612-1000-3R6 | P10: =VLOOKUP(N10,'Item Master 91223'!C:L,10,0) -> BG | Q10: 935-23587-xxxx-xxx label plan 20230522.xlsx [ 935-23587-0000-0R0_B02] | R10: Delta 0R0_B02
F11: B04 | G11: verified | H11: verified | I11: MODS_VER:618-23587-XXXX-MOD-40200 FLA_VER:618-23587-XXXX-FLA-39754 FLC_VER:618-23587-0000-FLC-39071 FTT_VER:618-23587-XXXX-FTT-37526 DCC_Ver:618-23587-XXXX-DCC-37528 SKU_VER:618-23587-0000-SKU-40116 | K11: 45499 | L11: 45499 | N11: 699-24612-1000-5R2 | O11: =VLOOKUP(N11,'Item Master 91223'!C:C,1,0) -> 699-24612-1000-5R2 | P11: =VLOOKUP(N11,'Item Master 91223'!C:L,10,0) -> BG | R11: Delta 0R0_B04
B12: 935-23587-0001-000 | C12: 40G | D12: 935-23587-0001-0R0 | E12: 692-2G506-0202-0R6 | F12: B02 | G12: ready | I12: MODS_VER:618-23587-XXXX-MOD-35851 FLA_VER:618-23587-XXXX-FLA-35675 FLC_VER:618-23587-0000-FLC-35743 FTT_VER:618-23587-XXXX-FTT-35587 SKU_VER:618-23587-0000-SKU-35762 | N12: 699-24612-1001-3R6
E13: 692-2G506-0202-0R2 692-2G506-0202-0R3 | F13: B04 | G13: ready | I13: MODS_VER:618-23587-XXXX-MOD-35851 FLA_VER:618-23587-XXXX-FLA-35675 FLC_VER:618-23587-0000-FLC-35743 FTT_VER:618-23587-XXXX-FTT-35587 SKU_VER:618-23587-0000-SKU-35762 | N13: 699-24612-1001-5R2
B14: 935-23587-0001-200 | C14: 80G | D14: 935-23587-0001-2R0 | E14: 692-2G506-0212-0R5/005 | F14: B02 | G14: ready | I14: MODS_VER:618-23587-XXXX-MOD-35851 FLA_VER:618-23587-XXXX-FLA-35675 FLC_VER:618-23587-0000-FLC-35743 FTT_VER:618-23587-XXXX-FTT-35587 SKU_VER:618-23587-0000-SKU-35764 | N14: 699-24612-1001-3R6/306
F15: B04 | G15: ready | I15: MODS_VER:618-23587-XXXX-MOD-35851 FLA_VER:618-23587-XXXX-FLA-35675 FLC_VER:618-23587-0000-FLC-35743 FTT_VER:618-23587-XXXX-FTT-35587 SKU_VER:618-23587-0000-SKU-35765 | N15: 699-24612-1001-5R2/502
B16: 935-23587-0011-200 | C16: 80G | D16: TBC | E16: TBC | F16: B04 | G16: ready | I16: MODS_VER:618-23587-XXXX-MOD-37122 FLA_VER:618-23587-XXXX-FLA-37154 FLC_VER:618-23587-0000-FLC-36863 FTT_VER:618-23587-XXXX-FTT-36449 SKU_VER:618-23587-0000-SKU-37375 | N16: TBC
B17: 935-23587-0011-201 | C17: 80G | D17: 935-23587-0011-2R1 | E17: 692-2G506-0216-0R0 692-2G510-0262-0R1 | F17: B04 | G17: ready | I17: MODS_VER:618-23587-XXXX-MOD-37122 FLA_VER:618-23587-XXXX-FLA-37154 FLC_VER:618-23587-0000-FLC-36863 FTT_VER:618-23587-XXXX-FTT-36449 SKU_VER:618-23587-0000-SKU-37375 | N17: 699-24612-1001-5R2
B18: 935-23587-0000-001 | C18: 40G | D18: 935-23587-0000-0R1 | E18: 692-2G506-0200-0R6 692-2G510-0200-0R0 | F18: B04 | G18: verified | H18: verified | I18: MODS_VER:618-23587-XXXX-MOD-40200 FLA_VER:618-23587-XXXX-FLA-39754 FLC_VER:618-23587-XXXX-FLC-39071 FTT_VER:618-23587-XXXX-FTT-37526 DCC_VER:618-23587-XXXX-DCC-37528 SKU_VER:618-23587-XXXX-SKU-40116 | K18: 45499 | L18: 45504 | N18: 699-24612-1000-5R2 | O18: =VLOOKUP(N18,'Item Master 91223'!C:C,1,0) -> 699-24612-1000-5R2 | P18: =VLOOKUP(N18,'Item Master 91223'!C:L,10,0) -> BG | Q18: 935-23587-xxxx-xxx label plan 20230522.xlsx [ 935-23587-0000-0R1_PG510] 935-23587-xxxx-xxx label plan 20230522.xlsx [ 935-23587-0000-0R1_PG506] | R18: Delta 0000-0R1_B04
A19: Microsoft | B19: 935-23587-0000-200 | C19: 80G | D19: 935-23587-0000-2R0 | E19: 692-2G506-0210-0R6 | F19: B02 | G19: verified | H19: verified | I19: MODS_VER:618-23587-XXXX-MOD-40200 FLA_VER:618-23587-XXXX-FLA-39754 FLC_VER:618-23587-0000-FLC-39071 FTT_VER:618-23587-XXXX-FTT-37526 DCC_VER:618-23587-XXXX-DCC-37528 SKU_VER:618-23587-XXXX-SKU-40117 | K19: 45499 | L19: 45499 | N19: 699-24612-1000-3R6 | O19: =VLOOKUP(N19,'Item Master 91223'!C:C,1,0) -> 699-24612-1000-3R6 | P19: =VLOOKUP(N19,'Item Master 91223'!C:L,10,0) -> BG | R19: Delta 2R0_B02
E20: 692-2G506-0210-0R6 692-2G510-0210-0R2 | F20: B04 | G20: verified | H20: verified | I20: MODS_VER:618-23587-XXXX-MOD-40200 FLA_VER:618-23587-XXXX-FLA-39754 FLC_VER:618-23587-0000-FLC-39071 FTT_VER:618-23587-XXXX-FTT-37526 DCC_VER:618-23587-XXXX-DCC-37528 SKU_VER:618-23587-XXXX-SKU-40117 | K20: 45303 | L20: 45499 | N20: 699-24612-1000-5R2 | O20: =VLOOKUP(N20,'Item Master 91223'!C:C,1,0) -> 699-24612-1000-5R2 | P20: =VLOOKUP(N20,'Item Master 91223'!C:L,10,0) -> BG | Q20: 935-23587-0000-xxx label plan v9 04272023.xlsx [ 935-23587-0000-2R0_B04] | R20: Delta 2R0_B04
B21: 935-23587-0000-201 | C21: 80G | D21: 935-23587-0000-2R1 | E21: 692-2G506-0210-0R6 692-2G510-0210-0R3 692-2G510-0210-0R2 | F21: B04 | G21: verified | H21: verified | I21: MODS_VER:618-23587-XXXX-MOD-40200 FLA_VER:618-23587-XXXX-FLA-39754 FLC_VER:618-23587-0000-FLC-39071 FTT_VER:618-23587-XXXX-FTT-37526 DCC_VER:618-23587-XXXX-DCC-37528 SKU_VER:618-23587-XXXX-SKU-40117 | K21: 45303 | L21: 45434 | N21: 699-24612-1000-5R2 | O21: =VLOOKUP(N21,'Item Master 91223'!C:C,1,0) -> 699-24612-1000-5R2 | P21: =VLOOKUP(N21,'Item Master 91223'!C:L,10,0) -> BG | Q21: 935-23587-xxxx-xxx label plan 20230522.xlsx [935-23587-0000-2R1_PG506] 935-23587-xxxx-xxx label plan 20230522.xlsx [935-23587-0000-2R1_PG510] | R21: Delta_0000_2R1_B04
B22: 935-23587-0000-204 | C22: 80G | D22: 935-23587-0000-2R4 | E22: 692-2G506-0210-0R6 | F22: D01 | G22: verified | H22: verified | I22: MODS_VER:618-23587-XXXX-MOD-40200 FLA_VER:618-23587-XXXX-FLA-39754 FLC_VER:618-23587-XXXX-FLC-40602 FTT_VER:618-23587-XXXX-FTT-37526 DCC_VER:618-23587-XXXX-DCC-37528 SKU_VER:618-23587-XXXX-SKU-39983 | K22: 45567 | L22: 45567 | M22: ECO341972 | N22: 699-24612-1000-9R0 965-24612-0000-100 | O22: =VLOOKUP(N22,'Item Master 91223'!C:C,1,0) -> #N/A | P22: =VLOOKUP(N22,'Item Master 91223'!C:L,10,0) -> #N/A
B23: 935-23587-0001-200 | C23: 80G | D23: 935-23587-0001-2R0 | E23: 692-2G506-0212-0R5 | F23: B04 | N23: 699-24612-1001-5R2 | O23: =VLOOKUP(N23,'Item Master 91223'!C:C,1,0) -> #N/A | P23: =VLOOKUP(N23,'Item Master 91223'!C:L,10,0) -> #N/A
A24: AWS | B24: 935-23587-A800-000 | C24: 40G | D24: 935-23587-A800-0R1 | E24: 692-2G506-0200-0R6 | F24: B02 | G24: verified | H24: verified | I24: MODS_VER:618-23587-XXXX-MOD-40200 FLA_VER:618-23587-XXXX-FLA-39754 FLC_VER:618-23587-XXXX-FLC-39071 FTT_VER:618-23587-XXXX-FTT-37526 DCC_VER:618-23587-XXXX-DCC-37528 SKU_VER:618-23587-XXXX-SKU-40116 | K24: 45609 | L24: 45614 | N24: 699-24612-1000-3R6 | O24: =VLOOKUP(N24,'Item Master 91223'!C:C,1,0) -> 699-24612-1000-3R6 | P24: =VLOOKUP(N24,'Item Master 91223'!C:L,10,0) -> BG | Q24: 935-23587-A800-0R1_B02 label plan 20230906.xlsx | R24: Delta A800_0R1_B02
B25: 935-23587-A800-001 | C25: 40G
B26: 935-23587-A800-002 | C26: 40G | D26: 935-23587-A800-0R2 | E26: 692-2G506-0200-006 692-2G506-0200-0R6 | F26: B04 | G26: verified | H26: verified | I26: MODS_VER:618-23587-XXXX-MOD-39151 FLA_VER:618-23587-XXXX-FLA-39070 FLC_VER:618-23587-XXXX-FLC-37527 FTT_VER:618-23587-XXXX-FTT-37526 DCC_VER:618-23587-XXXX-DCC-37528 SKU_VER:618-23587-XXXX-SKU-39077 | K26: 45426 | L26: 45427 | N26: 699-24612-1000-5R2
B27: 935-23587-A800-201 | C27: 80G | D27: 935-23587-A800-2R1 | E27: 692-2G506-0210-0R6 692-2G510-0210-0R2 | F27: B04 | G27: verified | H27: verified | I27: MODS:618-23587-XXXX-MOD-38175 FLA:618-23587-XXXX-FLA-37501 FLC:618-23587-XXXX-FLC-37527 FTT:618-23587-XXXX-FTT-37526 DCC:618-23587-XXXX-DCC-37528 SKU:618-23587-XXXX-SKU-38112 | K27: 45295 | L27: 45295 | N27: 699-24612-1000-5R2 | O27: =VLOOKUP(N27,'Item Master 91223'!C:C,1,0) -> 699-24612-1000-5R2 | P27: =VLOOKUP(N27,'Item Master 91223'!C:L,10,0) -> BG | Q27: 935-23587-xxxx-xxx label plan 20230522.xlsx [935-23587-A800-2R1_B04_PG506] | R27: Delta A800_2R1_B04
B28: 935-23587-A800-004 | C28: 40G | D28: 935-23587-A800-0R4 | F28: D01
B29: 935-23587-A800-204 | C29: 80G | D29: 935-23587-A800-2R4 | E29: 692-2G510-0210-0R2 692-2G510-0210-0R3 692-2G506-0210-0R6 692-2G506-0210-0R7 692-2G506-0210-0R8 692-2G506-0210-0R9 | F29: D01 | G29: verified | I29: MODS_VER:618-23587-XXXX-MOD-40200 FLA_VER:618-23587-XXXX-FLA-39754 FLC_VER:618-23587-XXXX-FLC-40602 FTT_VER:618-23587-XXXX-FTT-37526 DCC_VER:618-23587-XXXX-DCC-37528 SKU_VER:618-23587-XXXX-SKU-39983 | K29: 45657 | L29: 45657 | N29: 699-24612-1000-9R0 965-24612-0000-100
A30: HPE | B30: 935-23587-0301-200 | C30: 80G | D30: 935-23587-0301-2R0 | E30: 692-2G506-0212-0R5 | F30: B04 | G30: ready | N30: 699-24612-1001-5R2 | P30: =VLOOKUP(N30,'Item Master 91223'!C:L,10,0) -> #N/A
B31: 935-23587-0300-000 | C31: 40G | D31: 935-23587-0300-0R0 | E31: 692-2G506-0200-0R6 | F31: B02 | G31: verified | I31: MOD:618-23587-XXXX-MOD-40200 FLA:618-23587-XXXX-FLA-39754 FLC:618-23587-XXXX-FLC-40602 FTT:618-23587-XXXX-FTT-37526 SKU:618-23587-0000-SKU-42135 DCC:618-23587-XXXX-DCC-37528 | K31: 45725 | N31: 699-24612-1000-3R6 | O31: =VLOOKUP(N31,'Item Master 91223'!C:C,1,0) -> 699-24612-1000-3R6 | P31: =VLOOKUP(N31,'Item Master 91223'!C:L,10,0) -> BG
F32: B04 | G32: verified | I32: MOD:618-23587-XXXX-MOD-40200 FLA:618-23587-XXXX-FLA-39754 FLC:618-23587-XXXX-FLC-40602 FTT:618-23587-XXXX-FTT-37526 SKU:618-23587-0000-SKU-42135 DCC:618-23587-XXXX-DCC-37528 | K32: 45725 | N32: 699-24612-1000-5R2 | O32: =VLOOKUP(N32,'Item Master 91223'!C:C,1,0) -> 699-24612-1000-5R2 | P32: =VLOOKUP(N32,'Item Master 91223'!C:L,10,0) -> BG
B33: 935-23587-0300-200 | C33: 80G | D33: 935-23587-0300-2R0 | E33: 692-2G506-0210-0R6 | F33: B02 | G33: verified | I33: MOD:618-23587-XXXX-MOD-40200 FLA:618-23587-XXXX-FLA-39754 FLC:618-23587-XXXX-FLC-40602 FTT:618-23587-XXXX-FTT-37526 SKU:618-23587-0000-SKU-42134 DCC:618-23587-XXXX-DCC-37528 | K33: 45725 | N33: 699-24612-1000-3R6 | O33: =VLOOKUP(N33,'Item Master 91223'!C:C,1,0) -> 699-24612-1000-3R6 | P33: =VLOOKUP(N33,'Item Master 91223'!C:L,10,0) -> BG
E34: 692-2G506-0210-0R6 692-2G510-0210-0R2 | F34: B04 | G34: verified | I34: MOD:618-23587-XXXX-MOD-40200 FLA:618-23587-XXXX-FLA-39754 FLC:618-23587-XXXX-FLC-40602 FTT:618-23587-XXXX-FTT-37526 SKU:618-23587-0000-SKU-42134 DCC:618-23587-XXXX-DCC-37528 | K34: 45725 | N34: 699-24612-1000-5R2 | O34: =VLOOKUP(N34,'Item Master 91223'!C:C,1,0) -> 699-24612-1000-5R2 | P34: =VLOOKUP(N34,'Item Master 91223'!C:L,10,0) -> BG
B35: 935-23587-0301-000 | C35: 40G | D35: 935-23587-0301-0R0 | E35: 692-2G506-0202-006 | F35: B02 | G35: ready | I35: MODS_VER:618-23587-XXXX-MOD-35851 FLA_VER:618-23587-XXXX-FLA-35675 FLC_VER:618-23587-0000-FLC-35743 FTT_VER:618-23587-XXXX-FTT-35587 SKU_VER:618-23587-0000-SKU-35762 | N35: 699-24612-1001-3R6 | O35: =VLOOKUP(N35,'Item Master 91223'!C:C,1,0) -> #N/A | P35: =VLOOKUP(N35,'Item Master 91223'!C:L,10,0) -> #N/A
E36: 692-2G506-0202-006 692-2G506-0202-0R6 | F36: B04 | G36: ready | I36: MODS_VER:618-23587-XXXX-MOD-35851 FLA_VER:618-23587-XXXX-FLA-35675 FLC_VER:618-23587-0000-FLC-35743 FTT_VER:618-23587-XXXX-FTT-35587 SKU_VER:618-23587-0000-SKU-35762 | N36: 699-24612-1001-5R2 | O36: =VLOOKUP(N36,'Item Master 91223'!C:C,1,0) -> #N/A | P36: =VLOOKUP(N36,'Item Master 91223'!C:L,10,0) -> #N/A
B37: 935-23587-0300-204 | C37: 80G | D37: 935-23587-0300-2R4 | E37: 692-2G506-0210-0R6 692-2G506-0210-0R7 692-2G506-0210-0R8 692-2G506-0210-0R9 692-2G510-0210-0R2 692-2G510-0210-0R3 | F37: D01 | G37: verified | H37: verified | I37: MODS_VER:618-23587-XXXX-MOD-40200 FLA_VER:618-23587-XXXX-FLA-39754 FLC_VER:618-23587-XXXX-FLC-40602 FTT_VER:618-23587-XXXX-FTT-37526 DCC_VER:618-23587-XXXX-DCC-37528 SKU_VER:618-23587-XXXX-SKU-39983 | K37: 45700 | L37: 45700 | N37: 699-24612-1000-9R0
B38: 935-23587-0301-204 | C38: 80G | D38: 935-23587-0301-2R4 | E38: 692-2G510-0212-0R2 692-2G510-0212-0R3 692-2G506-0212-0R5 692-2G506-0212-0R6 | F38: D01 | G38: ready | N38: 699-24612-1001-9R0
A39: Microsoft | B39: 935-23587-0010-201 | C39: 80G | D39: 935-23587-0010-2R1 | E39: 692-2G506-0215-0R1 692-2G506-0215-0R0 | F39: B04 | G39: ready | N39: 699-24612-1000-5R2
B40: 935-23587-0010-204 | C40: 80G | D40: 935-23587-0010-2R4 | E40: 692-2G510-0260-0R0 692-2G510-0215-0R0 692-2G510-0215-0R1 692-2G506-0260-0R0 692-2G506-0215-0R0 692-2G506-0215-0R1 | F40: D01 /A800 | G40: ready | N40: 699-24612-1000-9R0 | O40: =VLOOKUP(N40,'Item Master 91223'!C:C,1,0) -> #N/A | P40: =VLOOKUP(O40,'Item Master 91223'!D:D,1,0) -> #N/A
...

Sheet FRU(Delta)_PN
A1: Customer | B1: Possible return Part Number | C1: Build-As | D1: B02/B04 | E1: Sorting Diag | F1: Online Diag | G1: Diag Version | H1: Diag Version Change Summary | I1: Diag Release Date | J1: Diag Varify Date | K1: ECO # | L1: BB PN | M1: Serviceme | N1: Serviceme big category | O1: LABEL PLAN | P1: LABEL FILE | Q1: Remarks
A2: MSFT | B2: 965-24612-0000-000 | C2: 965-24612-0000-0R0 | D2: B04 | E2: verified | F2: verified | G2: GB_FRU:Delta_CRU_ROM_B04_Board_965-24612-0000-0R0_699-5R2_v9.0 | I2: 45329 | J2: 45331 | L2: 699-24612-1000-5R2 | M2: =VLOOKUP(L2,'Item Master 91223'!C:C,1,0) -> 699-24612-1000-5R2 | N2: M06
B3: 965-24612-0000-0R0 | C3: 965-24612-0000-0R0

Sheet LUNAGPU_PN
A1: Possible return Part Number | B1: Wistron PN | C1: 40G/80G | D1: Build-As | E1: Build-as WPN | F1: B02/B04/D01 | G1: Sorting Diag | H1: Online Diag | I1: Diag Version | J1: Diag Version Change Summary | K1: Diag Release Date | L1: Diag Varify Date | M1: ECO # | N1: SXM PN | O1: GBB PN | P1: GBP PN | Q1: Sorting Diag | R1: Online Diag | S1: Serviceme | T1: Serviceme big category | U1: LABEL PLAN | V1: LABEL FILE
A2: 965-23687-0017-000 | B2: 591.06928.0020 | C2: 40G | D2: 965-23687-0017-0R4 | E2: 591.06928.0077 | F2: B04 | G2: verified | H2: verified | I2: Luna_40G_A100_GPU_FRU_B04_diag LunaFRU.965-23687-0017-0R4_FRU_RMA_FLA_2407 LunaFRU.965-23687-0017-0R4_FRU_RMA_FCT_2407 LunaFRU.965-23687-0017-0R4_FRU_RMA_RIN_2407 | K2: 45520 | L2: 45524 | N2: 692-2G506-0200-0R6 692-2G510-0200-0R0 692-2G510-0200-000 692-2G506-0200-006 | O2: 699-24612-1000-5R2 | P2: 675-23587-0000-5R9 | Q2: verified | R2: verified | S2: =VLOOKUP(O2,'Item Master 91223'!C:C,1,0) -> 699-24612-1000-5R2 | T2: =VLOOKUP(O2,'Item Master 91223'!C:L,10,0) -> BG | U2: B04 X 40G_20230427.xlsx | V2: Luna Delta-B04-40G | W2: Need to replace B02 board to B04
A3: 965-23687-0017-001 | B3: 591.06928.0027 | E3: 591.06928.0077
A4: 965-23687-0017-002 | B4: 591.06928.0032 | E4: 591.06928.0077
A5: 965-23687-0017-003 | B5: 591.06928.0050 | E5: 591.06928.0077
A6: 965-23687-0017-004 | B6: 591.06928.0066 | E6: 591.06928.0077
A7: 965-23687-0017-0R2 | B7: 591.06928.0043 | E7: 591.06928.0077
A8: 965-23687-0017-0R4 | B8: 591.06928.0077 | E8: 591.06928.0077
A9: 965-23687-0023-000 | B9: 591.06928.0023 | C9: 80G | D9: 965-23687-0023-0R4 | E9: 591.06928.0079 | F9: B04 | G9: verified | H9: verified | I9: Luna_80G_A100_GPU_FRU_B04_diag LunaFRU.965-23687-0023-0R4_FRU_RMA_FLA_2407 LunaFRU.965-23687-0023-0R4_FRU_RMA_FCT_2407 LunaFRU.965-23687-0023-0R4_FRU_RMA_RIN_2407 | K9: 45520 | L9: 45524 | N9: 692-2G506-0210-0R6 692-2G510-0210-0R3 692-2G510-0210-003 692-2G506-0210-006 | O9: 699-24612-1000-5R2 | P9: 675-23587-1000-5R9/ 670-23587-1000-5R8 | Q9: verified | R9: verified/ ready | S9: =VLOOKUP(O9,'Item Master 91223'!C:C,1,0) -> 699-24612-1000-5R2 | T9: =VLOOKUP(O9,'Item Master 91223'!C:L,10,0) -> BG | U9: B04 X 80G_20230420.xlsx | V9: Luna Delta-B04-80G
A10: 965-23687-0023-001 | B10: 591.06928.0025 | E10: 591.06928.0079
A11: 965-23687-0023-002 | B11: 591.06928.0031 | E11: 591.06928.0079
A12: 965-23687-0023-003 | B12: 591.06928.0056 | E12: 591.06928.0079
A13: 965-23687-0023-004 | B13: 591.06928.0067 | E13: 591.06928.0079
A14: 965-23687-0023-0R2 | B14: 591.06928.0059 | E14: 591.06928.0079
A15: 965-23687-0023-0R4 | B15: 591.06928.0079 | E15: 591.06928.0079
A16: 965-23687-0017-0R5 | B16: 591.06928.0081 | C16: 40G | D16: 965-23687-0017-0R5 | E16: 591.06928.0081 | F16: B02 | G16: verified | H16: verified | I16: Luna_40G_GPU_FRU_FW7.1_RMA LunaFRU.965-23687-0017-0R5_FRU_RMA_FLA_2310 LunaFRU.965-23687-0017-0R5_FRU_RMA_FCT_2310 LunaFRU.965-23687-0017-0R5_FRU_RMA_RIN_2310 | L16: 45251 | N16: 692-2G506-0200-0R6 692-2G506-0200-006 | O16: 699-24612-1000-3R6
A17: 965-23687-0023-0R5 | B17: 591.06928.0083 | C17: 80G | D17: 965-23687-0023-0R5 | E17: 591.06928.0083 | F17: B02 | G17: verified | H17: verified | I17: Luna_80G_A100_GPU_FRU_B02_diag LunaFRU.965-23687-0023-0R5_FRU_RMA_FLA_2407 LunaFRU.965-23687-0023-0R5_FRU_RMA_FCT_2407 LunaFRU.965-23687-0023-0R5_FRU_RMA_RIN_2407 | K17: 45520 | L17: 45552 | N17: 692-2G506-0210-0R6 692-2G506-0210-006 | O17: 699-24612-1000-3R6 | P17: 675-23587-1000-0R6 | R17: verified
A18: 965-23687-0039-0R1 | B18: 591.06928.0085 | C18: 80G | D18: 965-23687-0039-0R1 | E18: 591.06928.0085 | F18: D01 | G18: verified | H18: verified | I18: Luna_80G_GPU_FRU_FW9_A800_D01_RMA LunaFRU.965-23687-0039-0R1_FRU_FLA_D01_2407 LunaFRU.965-23687-0039-0R1_FRU_FCT_D01_2407 LunaFRU.965-23687-0039-0R1_FRU_RIN_D01_2407 | K18: 45484 | L18: 45489 | N18: 965-2G506-0041-201 | O18: 699-24612-1000-900 699-24612-1000-9R0 | P18: 675-23587-1010-8R0
A19: 965-23687-0023-0R2 | B19: 591.06928.0059 | C19: 80G | D19: 965-23687-0023-0R2 | E19: 591.06928.0059 | F19: B02 | G19: verified | H19: verified | I19: LunaFRU.965-23687-80G_HC-AC_rework_FLA_2405 LunaFRU.965-23687-0023-0R2_FRU_RMA_FCT_2405 LunaFRU.965-23687-0023-0R2_FRU_RMA_RIN_2405 | K19: 45238 | L19: 45454 | N19: 692-2G506-0210-0R6 692-2G506-0210-006 | O19: 699-24612-1000-3R6 699-24612-1000-306
A20: 965-23687-0017-000 | B20: 591.06928.0020 | C20: 40G | D20: 965-23687-0017-0R6 | E20: 591.06928.0087 | F20: D01 | G20: verified | H20: verified | I20: LunaFRU.965-23687-0017-0R6_FRU_RMA_FLA_2407 LunaFRU.965-23687-0017-0R6_FRU_RMA_FCT_2407 LunaFRU.965-23687-0017-0R6_FRU_RMA_RIN_2407 | K20: 45520 | L20: 45583 | N20: 692-2G510-0200-000 692-2G506-0200-0R6 692-2G506-0200-006 | O20: 699-24612-1000-900 699-24612-1000-9R0 965-24612-0000-100 | P20: 675-23587-1002-8R2 (506 GPU BB)
A21: 965-23687-0017-001 | B21: 591.06928.0027
A22: 965-23687-0017-002 | B22: 591.06928.0032
A23: 965-23687-0017-003 | B23: 591.06928.0050
A24: 965-23687-0017-004 | B24: 591.06928.0066
A25: 965-23687-0017-005
A26: 965-23687-0017-0R5 | B26: 591.06928.0081
A27: 965-23687-0017-0R2 | B27: 591.06928.0043
A28: 965-23687-0017-0R4 | B28: 591.06928.0077
A29: 965-23687-0017-0R6 | B29: 591.06928.0087
A30: 965-23687-0023-000 | B30: 591.06928.0023 | C30: 80G | D30: 965-23687-0023-0R6 | E30: 591.06928.0089 | F30: D01 | G30: verified | H30: verified | I30: LunaFRU.965-23687-0023-0R6_FRU_D01_FLA_2407 LunaFRU.965-23687-0023-0R6_FRU_D01_FCT_2407 LunaFRU.965-23687-0023-0R6_FRU_D01_RIN_2407 | K30: 45520 | L30: 45587 | N30: 692-2G506-0210-006 692-2G506-0210-0R6 692-2G506-0210-0R3 692-2G510-0210-0R3 692-2G510-0210-003 | O30: 699-24612-1000-900 699-24612-1000-9R0 965-24612-0000-100 | P30: 675-23587-1000-8R0 (506 GPU BB)
A31: 965-23687-0023-001 | B31: 591.06928.0025
A32: 965-23687-0023-002 | B32: 591.06928.0031
A33: 965-23687-0023-003 | B33: 591.06928.0056
A34: 965-23687-0023-004 | B34: 591.06928.0067
A35: 965-23687-0023-005 | B35: 591.06928.0082
A36: 965-23687-0023-0R5 | B36: 591.06928.0083
A37: 965-23687-0023-0R2 | B37: 591.06928.0059
A38: 965-23687-0023-0R4 | B38: 591.06928.0079
A39: 965-23687-0023-0R6 | B39: 591.06928.0089

Sheet LUNACPU_PN
A1: Possible return Part Number | B1: Wistron PN | C1: Build-As | D1: Build-as WPN | E1: Type | F1: Sorting Diag | G1: Online Diag | H1: Diag Version | I1: Diag Version Change Summary | J1: Diag Release Date | K1: Diag Varify Date | L1: ECO # | M1: LABEL PLAN | N1: LABEL FILE
A2: 965-23687-0012-000 | B2: 591.06928.0015 | C2: 965-23687-0012-0R4 | D2: 591.06928.0055 | E2: A100 | F2: verified | H2: Luna_40G_A100_CPU_Update9 LunaFRU.965-23687-0012-0R4_FRU_FLA_2408 LunaFRU.965-23687-0012-0R4_FRU_FCT_2408 | J2: 45534 | K2: 45544 | M2: Luna CPU tray label plan 20230613.xlsx
A3: 965-23687-0012-001 | B3: 591.06928.0026
A4: 965-23687-0012-002 | B4: 591.06928.0030
A5: 965-23687-0012-004 | B5: 591.06928.0053
A6: 965-23687-0012-0R2 | B6: 591.06928.0041
A7: 965-23687-0012-0R4 | B7: 591.06928.0055
A8: 965-23687-0034-000 | B8: 591.06928.0040
A9: 965-23687-0012-0R4 | B9: 591.06928.0055 | C9: 965-23687-0012-0R4 | D9: 591.06928.0055 | E9: A800 | G9: verified | H9: Luna_80G_FW9_A800_S2 Luna.670-23687-1800-100_S2_FLA_2406 Luna.670-23687-1800-100_S2_FCT_2406 | J9: 45490 | K9: 45503 | M9: Luna A800 S2

Sheet LUNA_S4_PN
A1: Possible return Part Number | B1: Wistron PN | C1: Build-As | D1: Build-as WPN | E1: Sorting Diag | F1: Online Diag | G1: Diag Version | H1: Diag Version Change Summary | I1: Diag Release Date | J1: Diag Varify Date | K1: ECO # | L1: LABEL PLAN | M1: LABEL FILE
A2: 675-23687-0203-000 675-23687-0800-0R0 | B2: 920-23687-2535-0R0 | C2: 675-23687-0203-000 675-23687-0800-0R0 | D2: 920-23687-2535-0R0 | F2: verified | G2: Luna_80G_FW9_A800_S4 Luna.675-23687-0800-0R0_S4_FLA_D01_2406 Luna.675-23687-0800-0R0_S4_FCT_D01_2406 Luna.675-23687-0800-0R0_S4_RIN_D01_2406 Luna.675-23687-0800-0R0_S4_FINT_D01_2406 | I2: 45499 | J2: 45507

Sheet LUNA_Frontcage_PN
A1: Possible return Part Number | B1: Wistron PN | C1: Build-As | D1: Build-as WPN | E1: Sorting Diag | F1: Online Diag | G1: Diag Version | H1: Diag Version Change Summary | I1: Diag Release Date | J1: Diag Varify Date | K1: ECO # | L1: HGX H100 | M1: Description
A2: 965-23687-0014-000 | B2: 591.06928.0018 | C2: 965-23687-0014-0R2 | D2: 591.06928.0042 | F2: verified | G2: Luna_40G_Front_Cage_FRU_FW7.1_Old_PSU_Support_RMA LunaFRU.965-23687-0014-0R2_FRU_FLA_2311 LunaFRU.965-23687-0014-0R2_FRU_FCT_2311 | J2: 45471 | L2: Front Cage & Mid-Plane Assembly | M2: Y182AR4 LUNA L10 SYSTEM ME PARTS
A3: 965-23687-0014-001 | B3: 591.06928.0029 | L3: Front Cage and Mid-Plane Assembly V1 | M3: Y182AR4 LUNA L10 SYSTEM ME PARTS
A4: 965-23687-0014-002 | B4: 591.06928.0028 | L4: Front Cage and Mid-Plane Assembly V2 | M4: Y182AR4 LUNA L10 SYSTEM ME PARTS
A5: 965-23687-0014-0R2 | B5: 591.06928.0042 | L5: Front Cage and Mid-Plane Assembly V2 | M5: Y182AR4 LUNA L10 SYSTEM ME PARTS

Sheet VULCAN_PN(H100)
A1: Customer | B1: Possible return Part Number | C1: 80G/96G | D1: Build-As | E1: SXM PN | F1: HMC PN | G1: Sorting Diag | H1: Online Diag | I1: Diag Version | J1: Diag Version Change Summary | K1: Diag Release Date | L1: Diag Varify Date | M1: ECO # | N1: BB PN | O1: Serviceme | P1: Serviceme big category | Q1: LABEL PLAN | R1: LABEL FILE | S1: Remarks
B2: 935-24287-0000-000 | C2: 80G | D2: 935-24287-0000-0R0 | E2: 692-2G520-0200-0R0/000 692-2G520-0200-0R2/002 | F2: 692-22312-0001-0R0/000 | G2: verified | H2: verified | I2: Q4V6 618-24287-XXXX-MFG-41663 | K2: 45614 | L2: 45621 | N2: 699-25612-0002-2R4 699-25612-0002-2R5 699-25612-0002-2R6
B3: 935-24287-0000-0R0 | C3: 80G | H3: verified
B4: 935-24287-0001-000 | C4: 80G | D4: 935-24287-0001-0R0 | E4: 692-2G520-0202-0R0/000 692-2G520-0202-0R2/002 | F4: 692-22312-0001-0R0/000 | G4: verified | H4: verified | I4: Q4V6 618-24287-XXXX-MFG-41663 | K4: 45614 | L4: 45618 | N4: 699-25612-0002-2R4 699-25612-0002-2R5 699-25612-0002-2R6
B5: 935-24287-0001-100 | C5: 80G | D5: 935-24287-0001-1R0 | E5: 692-2G520-0202-0R0/000 | F5: 692-22312-0001-0R0/000 | G5: verified | H5: verified | I5: Q4V6 618-24287-XXXX-MFG-41663 | K5: 45614 | L5: 45618 | N5: 699-25612-0002-2R5 699-25612-0002-2R6
B6: 935-24287-0010-300 | C6: 96G | D6: 935-24287-0010-3R0 | E6: 692-2G520-0221-0R0/000 | F6: 692-22312-0001-0R0/000 | G6: verified | H6: ready | I6: Q4V6 618-24287-XXXX-MFG-41663 | K6: 45614 | N6: 699-25612-0002-2R4 699-25612-0002-2R5 699-25612-0002-2R6
A7: Dell | B7: 935-24287-0100-000 | C7: 80G | D7: 935-24287-0100-0R0 | E7: 692-2G520-0200-0R0/000 692-2G520-0200-0R2/002 | F7: 692-22312-0001-0R0/000 | G7: verified | H7: verified | I7: Q4V6 618-24287-XXXX-MFG-41663 | K7: 45614 | L7: 45621 | N7: 699-25612-0002-2R4 699-25612-0002-2R5 699-25612-0002-2R6
A8: META | B8: 935-24287-A500-000 | C8: 80G | D8: 935-24287-A500-0R0 | E8: 692-2G520-0200-0R0/000 692-2G520-0200-0R2/002 | F8: 692-22312-0001-0R0/000 | G8: verified | H8: verified | I8: Q4V6 618-24287-XXXX-MFG-41663 | K8: 45614 | L8: 45663 | N8: 699-25612-0002-2R4 699-25612-0002-2R5 699-25612-0002-2R6
A9: Microsoft | B9: 935-24287-0900-000 | C9: 80G | D9: 935-24287-0900-0R0 | E9: 692-2G520-0200-0R0/000 692-2G520-0200-0R2/002 | F9: 692-22312-0001-0R0/000 | G9: verified | H9: verified | I9: Q4V6 618-24287-XXXX-MFG-41663 | K9: 45614 | L9: 45614 | N9: 699-25612-0002-2R4 699-25612-0002-2R5 699-25612-0002-2R6
B10: 935-24287-0900-0R0 | C10: 80G
A11: Line Failure | B11: 935-24287-0900-000 | C11: 80G | D11: 935-24287-0900-000 | E11: 692-2G520-0200-000 692-2G520-0200-002 | F11: 692-22312-0001-000 | G11: verified | H11: verified | I11: Q4V6 618-24287-XXXX-MFG-41663 | K11: 45614 | L11: 45636 | N11: 699-25612-0002-204 699-25612-0002-205 699-25612-0002-206
A12: Google | B12: 935-24287-6300-000 | C12: 80G | D12: 935-24287-6300-0R0 | E12: 692-2G520-0200-0R0/000 692-2G520-0200-0R2/002 | F12: 692-22312-0001-0R0/000 | G12: verified | H12: verified | I12: Q4V6 618-24287-XXXX-MFG-41663 | K12: 45614 | L12: 45640 | N12: 699-25612-0002-2R4 699-25612-0002-2R5 699-25612-0002-2R6
A13: AWS | B13: 935-24287-A800-000 | C13: 80G | D13: 935-24287-A800-0R0 | E13: 692-2G520-0200-0R0/000 692-2G520-0200-0R2/002 | F13: 692-22312-0001-0R0/000 | G13: verified | H13: verified | I13: Q4V6 618-24287-XXXX-MFG-41663 | K13: 45614 | L13: 45614 | N13: 699-25612-0002-2R4 699-25612-0002-2R5 699-25612-0002-2R6
B14: 935-24287-A800-0R0 | C14: 80G
A15: META | B15: 935-24287-A510-300 | C15: 96G | D15: 935-24287-A510-3R0 | E15: 692-2G520-0221-0R0/000 | F15: 692-22312-0001-0R0/000 | G15: verified | H15: verified | I15: Q4V6 618-24287-XXXX-MFG-41663 | K15: 45614 | L15: 45617 | N15: 699-25612-0002-2R4 699-25612-0002-2R5 699-25612-0002-2R6
B16: 935-24287-A510-3R0 | C16: 96G
A17: HPE | B17: 935-24287-0300-000 | C17: 80G | D17: 935-24287-0300-0R0 | E17: 692-2G520-0200-0R0/000 692-2G520-0200-0R2/002 | F17: 692-22312-0001-0R0/000 | G17: verified | H17: verified | I17: Q4V6 618-24287-XXXX-MFG-41663 | K17: 45614 | L17: 45644 | N17: 699-25612-0002-2R4 699-25612-0002-2R5 699-25612-0002-2R6

Sheet VULCAN_PN(H200)
A1: Customer | B1: Possible return Part Number | C1: 141G/G | D1: Build-As | E1: SXM PN | F1: HMC PN | G1: Sorting Diag | H1: Online Diag | I1: Diag Version | J1: Diag Version Change Summary | K1: Diag Release Date | L1: Diag Varify Date | M1: ECO # | N1: BB PN | O1: Serviceme | P1: Serviceme big category | Q1: LABEL PLAN | R1: LABEL FILE | S1: Remarks
A2: Lenovo | B2: 935-24287-2740-000 | C2: 141 | D2: 935-24287-2740-0R0
B3: 935-24287-2741-000 | C3: 141 | D3: 935-24287-2741-0R0
A4: MSFT | B4: 935-24287-0940-000 | C4: 141 | D4: 935-24287-0940-0R0 | E4: 692-2G520-0280-0R0/000 692-2G520-0280-0R1/001 695-2G520-0280-0R0 695-2G520-0280-0R1/001 | F4: 692-22312-0001-0R0/000 | G4: ready | H4: ready | I4: Q1V1 618-24287-XXXX-MFG-41974 | K4: 45698 | N4: 699-25612-0002-2R5 699-25612-0002-2R6
A5: Google | B5: 935-24287-6340-000 | C5: 141 | D5: 935-24287-6340-0R0 | E5: 692-2G520-0280-0R0/000 692-2G520-0280-0R1/001 695-2G520-0280-0R0 695-2G520-0280-0R1/001 | F5: 692-22312-0001-0R0/000 | G5: ready | H5: ready | I5: Q1V1 618-24287-XXXX-MFG-41974 | K5: 45698 | L5: 45708 | N5: 699-25612-0002-2R5 699-25612-0002-2R6
A6: HPE | B6: 935-24287-0340-000 | C6: 141 | D6: 935-24287-0340-0R0 | E6: 692-2G520-0280-0R0/000 692-2G520-0280-0R1/001 695-2G520-0280-0R0 695-2G520-0280-0R1/001 | F6: 692-22312-0001-0R0/000 | G6: verified | H6: verified | I6: Q1V1 618-24287-XXXX-MFG-41974 | K6: 45698 | N6: 699-25612-0002-2R5 699-25612-0002-2R6
A7: AWS | B7: 935-24287-A840-000 | C7: 141 | D7: 935-24287-A840-0R0 | E7: 692-2G520-0280-0R0/000 692-2G520-0280-0R1/001 695-2G520-0280-0R0 695-2G520-0280-0R1/001 | F7: 692-22312-0001-0R0/000 | G7: verified | H7: verified | I7: Q1V1 618-24287-XXXX-MFG-41974 | K7: 45698 | L7: 45722 | N7: 699-25612-0002-2R5 699-25612-0002-2R6
A8: DELL | B8: 935-24287-0140-000 | C8: 141 | D8: 935-24287-0140-0R0 | E8: 692-2G520-0280-0R0/000 692-2G520-0280-0R1/001 | F8: 692-22312-0001-0R0/000 | G8: ready | H8: ready | I8: Q1V1 618-24287-XXXX-MFG-41974 | K8: 45698 | N8: 699-25612-0002-2R5 699-25612-0002-2R6
A9: Generic | B9: 935-24287-0040-000 | C9: 141 | D9: 935-24287-0040-0R0 | E9: 692-2G520-0280-0R0/000 692-2G520-0280-0R1/001 695-2G520-0280-0R0 695-2G520-0280-0R1/001 | F9: 692-22312-0001-0R0/000 | G9: verified | H9: verified | I9: Q1V1 618-24287-XXXX-MFG-41974 | K9: 45698 | L9: 45698 | N9: 699-25612-0002-2R5 699-25612-0002-2R6
B10: 935-24287-0041-000 | C10: 141 | D10: 935-24287-0041-0R0 | E10: 692-2G520-0282-000/001 | F10: 692-22312-0001-0R0/000 | G10: ready | H10: ready | I10: Q1V1 618-24287-XXXX-MFG-41974 | K10: 45698 | N10: 699-25612-0002-2R5 699-25612-0002-2R6
B11: 935-24287-0041-100 | C11: 141 | D11: 935-24287-0041-1R0 | E11: 692-2G520-0282-0R0 692-2G520-0282-0R1 | F11: 692-22312-0001-0R0 | G11: verified | H11: verified | I11: Q1V1 618-24287-XXXX-MFG-41974 | K11: 45698 | L11: 45699 | N11: 699-25612-0002-2R5 699-25612-0002-2R6
A12: META | B12: 935-24287-A540-000 | C12: 141 | D12: 935-24287-A540-0R0 | E12: 692-2G520-0280-0R0/000 692-2G520-0280-0R1/001 695-2G520-0280-0R0 695-2G520-0280-0R1/001 | F12: 692-22312-0001-0R0/000 | G12: verified | H12: verified | I12: Q1V1 618-24287-XXXX-MFG-41974 | K12: 45698 | L12: 45699 | N12: 699-25612-0002-2R5 699-25612-0002-2R6

Sheet VULCAN_PN(H800)
A1: Customer | B1: Possible return Part Number | C1: 80G/96G | D1: Build-As | E1: SXM PN | F1: HMC PN | G1: Sorting Diag | H1: Online Diag | I1: Diag Version | J1: Diag Version Change Summary | K1: Diag Release Date | L1: Diag Varify Date | M1: ECO # | N1: BB PN | O1: Serviceme | P1: Serviceme big category | Q1: LABEL PLAN | R1: LABEL FILE | S1: Remarks
B2: 935-24287-00A0-000 | C2: 80G | D2: 935-24287-00A0-0R0 | E2: 692-2G520-0205-0R0/000 | F2: 692-22312-0001-0R0/000 | G2: verified | H2: ready | I2: Q1V1 618-24287-XXXX-MFG-41974 | K2: 45698 | L2: 45716 | N2: 699-25612-0002-2R4 699-25612-0002-2R5 699-25612-0002-2R6
A3: DELL | B3: 935-24287-01A0-000 | C3: 80G | D3: 935-24287-01A0-0R0 | E3: 692-2G520-0205-0R0/000 | F3: 692-22312-0001-0R0/000 | G3: verified | H3: ready | I3: Q1V1 618-24287-XXXX-MFG-41974 | K3: 45698 | N3: 699-25612-0002-2R4 699-25612-0002-2R5 699-25612-0002-2R6

Sheet VULCAN_PN(H20)
A1: Customer | B1: Possible return Part Number | C1: 80G/96G | D1: Build-As | E1: SXM PN | F1: HMC PN | G1: Sorting Diag | H1: Online Diag | I1: Diag Version | J1: Diag Version Change Summary | K1: Diag Release Date | L1: Diag Varify Date | M1: ECO # | N1: BB PN | O1: Serviceme | P1: Serviceme big category | Q1: LABEL PLAN | R1: LABEL FILE | S1: Remarks
B2: 935-24287-00M0-0R0 | C2: 96G | D2: 935-24287-00M0-0R0 | E2: 692-2G520-0236-0R0/000 692-2G520-0236-0R1/001 | F2: 692-22312-0001-0R0/000 | G2: ready | H2: ready | I2: Q1V1 618-24287-XXXX-MFG-41974 | K2: 45698 | L2: 45723 | N2: 699-25612-0002-2R4 699-25612-0002-2R5 699-25612-0002-2R6
B3: 935-24287-00N0-0R0 | C3: 141 | D3: 935-24287-00N0-0R0 | E3: 692-2G520-0266-000 | F3: 692-22312-0001-000 | G3: ready | H3: ready | I3: Q1V1 618-24287-XXXX-MFG-41974 | K3: 45698 | N3: 699-25612-0002-2R6
B4: 935-24287-00N1-0R0 | D4: 935-24287-00N1-0R0

Sheet FRU(Vulcan)_PN
A1: Customer | B1: Possible return Part Number | C1: Build-As | D1: HMC PN | E1: Sorting Diag | F1: Online Diag | G1: Diag Version | H1: Diag Version Change Summary | I1: Diag Release Date | J1: Diag Varify Date | K1: ECO # | L1: BB PN | M1: Serviceme | N1: Serviceme big category | O1: LABEL PLAN | P1: LABEL FILE | Q1: Remarks
A2: META | B2: 965-25612-A502-0R0 | C2: 965-25612-A502-0R0 | D2: 692-22312-0001-0R0 692-22312-0001-000 | E2: READY | F2: verified | G2: Q4V6 618-24287-XXXX-MFG-41663 | I2: 45698 | J2: 45728 | L2: 699-25612-0002-2R4 699-25612-0002-2R5 699-25612-0002-2R6
B3: 965-25612-0002-0R0 | C3: 965-25612-0002-0R0 | E3: READY | F3: verified | G3: Q4V6 618-24287-XXXX-MFG-41663 | I3: 45698 | L3: 699-25612-0002-2R6 699-25612-0002-2R4 699-25612-0002-2R5
A4: DELL | B4: 965-25612-0102-0R0 | C4: 965-25612-0102-0R0 | E4: READY | F4: verified | G4: Q4V6 618-24287-XXXX-MFG-41663 | I4: 45698 | L4: 699-25612-0002-2R6 699-25612-0002-2R4 699-25612-0002-2R5
B5: 965-25612-0102-000 | I5: 45698

Sheet REDSTONE_PN
A1: Customer | B1: Possible return Part Number | C1: 40G/64G/80G/96G | D1: Build-As | E1: SXM PN | F1: Sorting Diag | G1: Online Diag | H1: Diag Version | I1: Diag Version Change Summary | J1: Diag Release Date | K1: Diag Varify Date | L1: ECO # | M1: BB PN | N1: Serviceme | O1: Serviceme big category | P1: LABEL PLAN | Q1: LABEL FILE | R1: Remarks
B2: 935-22687-0030-000 | C2: 40G | D2: 935-22687-0030-0R0 | E2: 692-2G506-0202-0R2 692-2G506-0202-0R3 692-2G506-0202-0R6 692-2G506-0202-002 692-2G506-0202-003 692-2G506-0202-006 | F2: verified | G2: verified | H2: FLA:618-22687-XXXX-FLA-40262 FTT:618-22687-XXXX-FTT-40263 SKU:618-22687-0030-SKU-33974 MODS:618-22687-XXXX-MOD-40261 FLC:618-22687-XXXX-FLC-40273 | J2: 45289 | K2: 45460 | M2: 699-24597-0000-1R5 699-24597-0000-3R1
B3: 935-22687-0030-200 | C3: 80G | D3: 935-22687-0030-2R0 | E3: 692-2G506-0212-0R5 692-2G506-0212-0R2 692-2G506-0212-005 692-2G506-0212-002 | F3: verified | G3: verified | H3: FLA_VER:618-22687-XXXX-FLA-40286 FTT_VER:618-22687-XXXX-FTT-40263 SKU_VER:618-22687-XXXX-SKU-40183 MODS_VER:618-22687-XXXX-MOD-40285 FLC_VER:618-22687-XXXX-FLC-40273 | J3: 45638 | K3: 45661 | M3: 699-24597-0000-1R5 699-24597-0000-3R1
A4: Cray | B4: 935-22687-3830-000 | C4: 40G | D4: 935-22687-3830-0R0 | E4: 692-2G506-0202-0R2 692-2G506-0202-0R3 692-2G506-0202-0R6 692-2G506-0202-002 692-2G506-0202-003 692-2G506-0202-006 | M4: 699-24597-0000-1R5 699-24597-0000-3R1
A5: HPE | B5: 935-22687-0331-200 | C5: 80G | D5: 935-22687-0331-2R0 | E5: 692-2G506-0210-0R2 692-2G506-0210-0R8 692-2G506-0210-002 692-2G506-0210-008 | F5: verified | G5: verified | H5: FLA:618-22687-0030-FLA-33968 FLC:618-22687-0030-FLC-35230 FTT:618-22687-0030-FTT-33679 SKU:618-22687-0031-SKU-33975 MODS:618-22687-0030-MOD-33970 | J5: 45289 | K5: 45693 | M5: 699-24597-0000-1R5 699-24597-0000-3R1
B6: 935-22687-0331-000 | C6: 40G | D6: 935-22687-0331-0R0 | E6: 692-2G506-0200-0R2 692-2G506-0200-0R3 692-2G506-0200-0R6 692-2G506-0200-002 692-2G506-0200-003 692-2G506-0200-006 | M6: 699-24597-0000-1R5 699-24597-0000-3R1
B7: 935-22687-0330-000 | C7: 40G | D7: 935-22687-0330-0R0 | E7: 692-2G506-0202-002 692-2G506-0202-003 692-2G506-0202-006 692-2G506-0202-0R2 692-2G506-0202-0R3 692-2G506-0202-0R6 | M7: 699-24597-0000-1R5 699-24597-0000-3R1
B8: 935-22687-0330-300 | C8: 96G | D8: 935-22687-0330-3R0 | E8: 692-2G506-0232-000 692-2G506-0232-001 | M8: 699-24597-0000-3R1
B9: 935-22687-0030-300 | C9: 96G | D9: 935-22687-0030-3R0 | E9: 692-2G506-0232-000 692-2G506-0232-001 | M9: 699-24597-0000-3R1
B10: 935-22687-0030-400 | C10: 64G | D10: 935-22687-0030-4R0 | E10: 2 high PWR + 2 lower PWR 692-2G506-0242-001 692-2G506-0243-001 692-2G506-0242-0R1 692-2G506-0243-0R1 | F10: verified | G10: READY | H10: FLA_VER:618-22687-1001-FLA-33149 SKU_VER:618-22687-0030-SKU-33147 MODS_VER:618-22687-1001-MOD-33145 FLC_VER:618-22687-1001-FLC-32895 | J10: 45289 | M10: 699-24597-0000-3R1
B11: 935-22687-0031-000 | C11: 40G | D11: 935-22687-0031-0R0 | E11: 692-2G506-0200-002 692-2G506-0200-003 692-2G506-0200-006 692-2G506-0200-0R2 692-2G506-0200-0R3 692-2G506-0200-0R6 | M11: 699-24597-0000-1R5 699-24597-0000-3R1
A12: Lenovo | B12: 935-22687-2732-000 | C12: 40G | D12: 935-22687-2732-0R0 | E12: 692-2G506-0202-002 692-2G506-0202-003 692-2G506-0202-006 692-2G506-0202-0R2 692-2G506-0202-0R3 692-2G506-0202-0R6 | M12: 699-24597-0000-1R5 699-24597-0000-3R1
A13: Lenovo | B13: 935-22687-2732-200 | C13: 80G | D13: 935-22687-2732-2R0 | E13: 692-2G506-0212-0R5/005 692-2G510-0212-0R2/002 | F13: verified | G13: ready | H13: FLA_VER:618-22687-XXXX-FLA-40286 FTT_VER:618-22687-XXXX-FTT-40263 SKU_VER:618-22687-XXXX-SKU-40183 MODS_VER:618-22687-XXXX-MOD-40285 FLC_VER:618-22687-XXXX-FLC-40273 | J13: 45638 | M13: 699-24597-0000-3R1/301
B14: 935-22687-2730-000 | C14: 40G
A15: DELL | B15: 935-22687-0130-201 | C15: 80G | D15: 935-22687-0130-2R2 | E15: 692-2G510-0212-002 692-2G510-0212-0R2 692-2G506-0212-007 692-2G506-0212-0R7 | F15: verified | G15: verified | H15: FLA_VER:618-22687-XXXX-FLA-40286 FTT_VER:618-22687-XXXX-FTT-40263 SKU_VER:618-22687-XXXX-SKU-40183 MODS_VER:618-22687-XXXX-MOD-40285 FLC_VER:618-22687-XXXX-FLC-40273 | J15: 45453 | K15: 45455 | M15: 699-24597-0000-3R1 699-24597-0000-301
B16: 935-22687-0130-200
B17: 935-22687-0130-000 | C17: 40G | D17: 935-22687-0130-0R0 | E17: 692-2G506-0202-0R2 692-2G506-0202-0R3 692-2G506-0202-0R6 692-2G506-0202-002 692-2G506-0202-003 692-2G506-0202-006 | M17: 699-24597-0000-1R5 699-24597-0000-3R1
A18: Red October | B18: 694-22687-0030-2R0 | C18: 80G | D18: 694-22687-0030-2R0 | E18: 692-2G506-0212-005 692-2G506-0212-002 692-2G506-0212-0R2 692-2G506-0212-0R5 | F18: verified | G18: verified | H18: FLA_VER:618-22687-XXXX-FLA-40286 FTT_VER:618-22687-XXXX-FTT-40263 SKU_VER:618-22687-XXXX-SKU-40183 MODS_VER:618-22687-XXXX-MOD-40285 FLC_VER:618-22687-XXXX-FLC-40273 | J18: 45623 | K18: 45623 | M18: 699-24597-0000-1R5 699-24597-0000-3R1
B19: 694-22687-0030-200
B20: 694-22687-1000-000 | C20: 40G | D20: 694-22687-1000-0R0 | E20: 692-2G506-0202-0R2 692-2G506-0202-0R3 692-2G506-0202-0R6 692-2G506-0202-002 692-2G506-0202-003 692-2G506-0202-006 | H20: FLA:618-22687-0030-FLA-33968 FTT:618-22687-0030-FTT-33679 SKU:618-22687-0030-SKU-33974 MODS:618-22687-0030-MOD-33970 | M20: 699-24597-0000-1R5 699-24597-0000-3R1
A21: Generic | B21: 935-22687-0031-200 | C21: 80G | D21: 935-22687-0031-2R0 | E21: 692-2G506-0210-002 692-2G506-0210-0R2 692-2G506-0210-008 692-2G506-0210-0R8 | H21: FLA:618-22687-0030-FLA-33968 FTT:618-22687-0030-FTT-33679 SKU:618-22687-0031-SKU-33975 MOD:618-22687-0030-MOD-33970 | M21: 699-24597-0000-3R1 699-24597-0000-1R5

Sheet SCOUT_PN
A1: Customer | B1: Possible return Part Number | C1: 64G/80G/94G | D1: Build-As | E1: SXM PN | F1: Sorting Diag | G1: Online Diag | H1: Diag Version | I1: Diag Version Change Summary | J1: Diag Release Date | K1: Diag Varify Date | L1: ECO # | M1: BB PN | N1: Serviceme | O1: Serviceme big category | P1: LABEL PLAN | Q1: LABEL FILE | R1: Remarks
B2: 935-23087-0001-000 | C2: 80G | D2: 935-23087-0001-0R0 | E2: 692-2G520-0202-000/0R0 | F2: verified | G2: verified | H2: 618-23087-XXXX-MFG-39744 | J2: 45700 | K2: 45700 | M2: 699-23537-0001-101/1R1 699-23537-0001-100/1R0
B3: 935-23087-0021-300 | C3: 64G | D3: 935-23087-0021-3R0 | E3: 692-2G520-0213-000 | M3: 699-23537-0001-101
B4: 935-23087-0031-400 | C4: 94G | D4: 935-23087-0031-4R0 | E4: 692-2G520-0228-000/0R0 | H4: 618-23087-XXXX-MFG-42138 | J4: 45715 | M4: 699-23537-0001-101 699-23537-0001-100/1R0
A5: Dell | B5: 935-23087-0101-000 | C5: 80G | D5: 935-23087-0101-0R0 | E5: 692-2G520-0202-000/0R0 | F5: verified | G5: verified | H5: 618-23087-XXXX-MFG-40232 | J5: 45490 | K5: 45638 | M5: 699-23537-0001-101/1R1 699-23537-0001-100/1R0
A6: Dell | B6: 935-23087-0131-400 | C6: 94G | D6: 935-23087-0131-4R0 | E6: 692-2G520-0228-000/0R0 | H6: 618-23087-XXXX-MFG-40232 | M6: 699-23537-0001-101/1R1 699-23537-0001-100/1R0
A7: HPE | B7: 935-23087-0301-000 | C7: 80G | D7: 935-23087-0301-0R0 | E7: 692-2G520-0202-000/0R0 | F7: verified | G7: verified | H7: 618-23087-XXXX-MFG-41000 | J7: 45625 | K7: 45661 | M7: 699-23537-0001-101/1R1 699-23537-0001-100/1R0
A8: HPE | B8: 935-23087-0331-400 | C8: 94G | D8: 935-23087-0331-4R0 | E8: 692-2G520-0228-000 | F8: verified | G8: verified | H8: 618-23087-XXXX-MFG-39774 | J8: 45412 | K8: 45412 | M8: 699-23537-0001-101 699-23537-0001-100
A9: Lenovo | B9: 935-23087-270F-000 | C9: 80G | D9: 935-23087-270F-0R0 | E9: 692-2G520-0202-000 | F9: verified | G9: ready | H9: 618-23087-XXXX-MFG-40440 | J9: 45637 | M9: 699-23537-0001-101 699-23537-0001-100
A10: Lenovo | B10: 935-23087-273F-400 | C10: 94G | D10: 935-23087-273F-4R0 | E10: 692-2G520-0228-000/0R0 | H10: 618-23087-XXXX-MFG-40232 | M10: 699-23537-0001-101 699-23537-0001-100/1R0

Sheet VIKINGCPU_PN
A1: Possible return Part Number | B1: Wistron PN | C1: Build-As | D1: Build-as WPN | E1: Sorting Diag | F1: Online Diag | G1: Diag Version | H1: Diag Version Change Summary | I1: Diag Release Date | J1: Diag Varify Date | K1: ECO # | L1: LABEL PLAN | M1: LABEL FILE
A2: 965-24387-0002-000 | B2: 591.07L01.0007 | C2: 965-24387-0002-0R0 | D2: 591.07L01.0007 | E2: ready | F2: ready | G2: SBG_Viking_Fru_MB_Tray_Air_PT_S2_20231019 618-24387-XXXX-MFG-38904
A3: 965-24387-0002-000 | B3: 591.07L01.0007 | C3: 965-24387-0002-0R2 | D3: 591.07L01.0020 | E3: verified | F3: verified | G3: SBG_VikingFru_MB_Tray_Air_PT_S2_MP_RMA_24Q3_skip_stage OpsDiag_v1.0.35_20230721_Pure_wist_240911 618-24387-XXXX-MFG-40771 | I3: 45565 | J3: 45638
A4: 965-24387-0002-001 | B4: 591.07L01.0016
A5: 965-24387-0002-0R2 | B5: 591.07L01.0020
A6: 965-24387-0002-002 | B6: 591.07L01.0027

Sheet VIKINGGPU_PN
A1: Possible return Part Number | B1: Wistron PN | C1: 80G/96G | D1: Build-As | E1: Build-as WPN | F1: SXM PN | G1: HMC PN | H1: Sorting Diag | I1: Online Diag | J1: Diag Version | K1: Diag Version Change Summary | L1: Diag Release Date | M1: Diag Varify Date | N1: ECO # | O1: BB PN | P1: Serviceme | Q1: Serviceme big category | R1: LABEL PLAN | S1: LABEL FILE | T1: Remarks
A2: 965-24387-0001-000 | B2: 591.07L01.0001 | C2: 80G | D2: 965-24387-0001-0R0 | E2: 591.07L01.0028 | F2: 692-2G520-0200-0R0/000 | G2: 692-22312-0001-0R0 | H2: verified | I2: verified | J2: 618-24287-XXXX-MFG-39916 618-24387-XXXX-MFG-39757 | L2: 45397 | M2: 45397 | O2: 699-25612-0002-2R4 699-25612-0002-2R5
A3: 965-24387-0001-0R0 | B3: 591.07L01.0028

Sheet Viking_Frontcage_PN
A1: Possible return Part Number | B1: Wistron PN | C1: Build-As | D1: Build-as WPN | E1: Sorting Diag | F1: Online Diag | G1: Diag Version | H1: Diag Version Change Summary | I1: Diag Release Date | J1: Diag Varify Date | K1: ECO # | L1: HGX H100 | M1: Description
A2: 965-24387-0004-000 | B2: 591.07L01.0004 | C2: 965-24387-0004-0R0 | D2: 591.07L01.0030 | E2: verified | F2: verified | G2: 618-24387-XXXX-MFG-41010 | I2: 45593 | J2: 45593
A3: 965-24387-0004-0R0 | B3: 591.07L01.0030

Sheet Viking_H200_S4_PN
A1: Possible return Part Number | B1: Wistron PN | C1: Build-As | D1: Build-as WPN | E1: Sorting Diag | F1: Online Diag | G1: Diag Version | H1: Diag Version Change Summary | I1: Diag Release Date | J1: Diag Varify Date | K1: ECO # | L1: LABEL PLAN | M1: LABEL FILE
A2: 675-24387-0080-000 | B2: 920-24387-2542-000 | C2: 675-24387-0080-0R0 | D2: 920-24387-2542-0R0 | G2: 618-24387-XXXX-MFG-41245 | I2: 45656

Sheet Viking_H200_GPUTray
A1: Possible return Part Number | B1: Wistron PN | C1: 141G/G | D1: Build-As | E1: Build-as WPN | F1: SXM PN | G1: HMC PN | H1: Sorting Diag | I1: Online Diag | J1: Diag Version | K1: Diag Version Change Summary | L1: Diag Release Date | M1: Diag Varify Date | N1: ECO # | O1: BB PN
A2: 965-24387-0021-000 | B2: 591.07L01.0037 | C2: 141G | D2: 965-24387-0021-0R0 | E2: 591.07L01.0038 | F2: 692-2G520-0280-000 692-2G520-0280-001 | G2: 692-22312-0001-000 | I2: ready | J2: 618-24387-XXXX-MFG-40988 618-24287-XXXX-MFG-41974 | L2: 45698 | M2: 45735 | O2: 699-25612-0002-206/2R6

Sheet Umbriel_PN
A1: Customer | B1: Possible return Part Number | C1: 180G | D1: Build-As | E1: SXM PN | F1: HMC PN | G1: CX-7 PN | H1: Sorting Diag | I1: Online Diag | J1: Diag Version | K1: Diag Version Change Summary | L1: Diag Release Date | M1: Diag Varify Date | N1: ECO # | O1: BB PN | P1: Serviceme | Q1: Serviceme big category | R1: LABEL PLAN | S1: LABEL FILE | T1: Remarks
A2: generic | B2: 935-26287-00A0-0R0 | C2: 180G | D2: 935-26287-00A0-0R0 | E2: 692-2G525-0220-000/0R0 | F2: 692-22312-0003-000/0R0 | G2: 692-9X760-00SE-S00 | O2: 699-26612-0000-P00/PR0
A3: generic | B3: 935-26287-00A1-0R0 | C3: 180G | D3: 935-26287-00A1-0R0 | E3: 692-2G525-0225-000 | F3: 692-22312-0003-000 | G3: 692-9X760-00SE-S00 | O3: 699-26612-0000-P00
A4: Google | B4: 935-26287-63A0-0R0 | C4: 180G | D4: 935-26287-63A0-0R0 | E4: 692-2G525-0220-000/0R0 | F4: 692-22312-0003-000/0R0 | G4: 692-9X760-00SE-S00 | O4: 699-26612-0000-P00/PR0

Sheet VIKING_B200CPU_PN
A1: Possible return Part Number | B1: Wistron PN | C1: Build-As | D1: Build-as WPN | E1: Sorting Diag | F1: Online Diag | G1: Diag Version | H1: Diag Version Change Summary | I1: Diag Release Date | J1: Diag Varify Date | K1: ECO # | L1: LABEL PLAN | M1: LABEL FILE
A2: 965-24387-0017-0R0 | B2: 591.09Q01.0002 | C2: 965-24387-0017-0R0 | D2: 591.09Q01.0002

Sheet VIKING_B200GPU_PN
A1: Possible return Part Number | B1: Wistron PN | C1: 180G | D1: Build-As | E1: Build-as WPN | F1: SXM PN | G1: HMC PN | H1: CX-7 PN | I1: Sorting Diag | J1: Online Diag | K1: Diag Version | L1: Diag Version Change Summary | M1: Diag Release Date | N1: Diag Varify Date | O1: ECO # | P1: BB PN | Q1: Serviceme | R1: Serviceme big category | S1: LABEL PLAN | T1: LABEL FILE | U1: Remarks
A2: 965-24387-0018-0R0 | B2: 591.09Q01.0006 | C2: 180G | D2: 965-24387-0018-0R0 | E2: 591.09Q01.0006 | F2: 692-2G525-0220-000 | G2: 692-22312-0003-000 | H2: 692-9X760-00SE-S00 | P2: 699-26612-0000-P00

Sheet Viking_B200Frontcage_PN
A1: Possible return Part Number | B1: Wistron PN | C1: Build-As | D1: Build-as WPN | E1: Sorting Diag | F1: Online Diag | G1: Diag Version | H1: Diag Version Change Summary | I1: Diag Release Date | J1: Diag Varify Date | K1: ECO # | L1: HGX H100 | M1: Description
A2: 965-24387-0019-0R0 | B2: 591.09Q01.0007 | C2: 965-24387-0019-0R0 | D2: 591.09Q01.0007

Sheet Viking_B200_S4_PN
A1: Possible return Part Number | B1: Wistron PN | C1: Build-As | D1: Build-as WPN | E1: Sorting Diag | F1: Online Diag | G1: Diag Version | H1: Diag Version Change Summary | I1: Diag Release Date | J1: Diag Varify Date | K1: ECO # | L1: LABEL PLAN | M1: LABEL FILE
A2: 675-24387-0061-000 | B2: 920-24387-2561-000 | C2: 675-24387-0061-000 | D2: 920-24387-2561-000

Sheet Item Master 91223
A1: Project Code | B1: Plant | C1: PN | D1: FRUNO | E1: DESCR | F1: ABC | G1: FSD Time | H1: EOSL date | I1: Brand | J1: Product Line | K1: Customer Model | L1: Big Category | M1: Small Category | N1: Package PN | O1: Package Size | P1: TVRATIO | Q1: GWEIGHT | R1: NWEIGHT | S1: PACKAGING COST | T1: FREIGHT COST | U1: OEM | V1: Support Model | W1: Disposition | X1: Redemption | Y1: Supplier | Z1: Vender Warranty | AA1: Is Return | AB1: Is SN | AC1: IS HAZA | AD1: IS BATTERY | AE1: MO QTY | AF1: IS SALES | AG1: IS ACTIVE | AH1: IS IMEI | AI1: IMEI Flag | AJ1: IS CONSUME | AK1: BIS STD | AL1: BIS Registration | AM1: Vendor Purchase LT | AN1: MAC Flag | AO1: ER LT(Day) | AP1: Retrun Group | AQ1: Business Model | AR1: IS Delete
A2: NAOMI_CA | B2: F032 | C2: 591.06928.0015 | D2: 965-23687-0012-000 | E2: FRU DGX A100, CPU TRAY W/MOTHERBOARD | F2: A | I2: NVIDIA | L2: S03 | P2: 0 | W2: RET | AA2: N | AB2: N | AC2: N | AD2: N | AE2: 1 | AF2: N | AG2: Y | AH2: N | AI2: N | AM2: 0 | AR2: N
A3: NAOMI_CA | B3: F032 | C3: 591.06928.0026 | D3: 965-23687-0012-001 | E3: FRU DGX A100, CPU TRAY W/ MB VRHOT | F3: A | I3: NVIDIA | L3: S03 | P3: 0 | W3: RET | AA3: N | AB3: N | AC3: N | AD3: N | AE3: 1 | AF3: N | AG3: Y | AH3: N | AI3: N | AM3: 0 | AR3: N
A4: NAOMI_CA | B4: F032 | C4: 591.06928.0030 | D4: 965-23687-0012-002 | E4: FRU LUNA MB TRAY W/O DIMM NEW VICOR | F4: A | I4: NVIDIA | L4: S03 | P4: 0 | W4: RET | AA4: N | AB4: N | AC4: N | AD4: N | AE4: 1 | AF4: N | AG4: Y | AH4: N | AI4: N | AM4: 0 | AR4: N
A5: NAOMI_CA | B5: F032 | C5: 591.06928.0041 | D5: 965-23687-0012-0R2 | E5: FRU LUNA MB TRAY W/O DIMM NEW VICOR RMA | F5: A | I5: NVIDIA | L5: S03 | P5: 0 | W5: RET | AA5: N | AB5: N | AC5: N | AD5: N | AE5: 1 | AF5: N | AG5: Y | AH5: N | AI5: N | AM5: 0 | AR5: N
A6: NAOMI_CA | B6: F032 | C6: 591.06928.0055 | D6: 965-23687-0012-0R4 | E6: FRU LUNA RESPIN MB TRAY W/O DIMM RMA | F6: A | I6: NVIDIA | L6: S03 | P6: 0 | W6: RET | AA6: N | AB6: N | AC6: N | AD6: N | AE6: 1 | AF6: N | AG6: Y | AH6: N | AI6: N | AM6: 0 | AR6: N
A7: NAOMI_CA | B7: F032 | C7: 555.07M02.D078 | D7: 699-25612-0002-211 | E7: BOARD VULCAN GPU BBOARD 0002-211(D | F7: A | I7: NVIDIA | L7: SV | P7: 0 | W7: RET | AA7: N | AB7: N | AC7: N | AD7: N | AE7: 1 | AF7: N | AG7: Y | AH7: N | AI7: N | AM7: 0 | AR7: N
A8: NAOMI_CA | B8: F032 | C8: 581.07M10.0161 | D8: 935-24287-00A1-000 | E8: HGX H800 8 GPU, SXM5 80GB HBM3 PC | F8: A | I8: NVIDIA | L8: SV | P8: 0 | W8: RET | AA8: N | AB8: N | AC8: N | AD8: N | AE8: 1 | AF8: N | AG8: Y | AH8: N | AI8: N | AM8: 0 | AR8: N
A9: NAOMI_CA | B9: F032 | C9: 581.07M10.0163 | D9: 935-24287-00A1-000 | E9: HGX H800 8 GPU, SXM5 80GB HBM3 PC | F9: A | I9: NVIDIA | L9: SV | P9: 0 | W9: RET | AA9: N | AB9: N | AC9: N | AD9: N | AE9: 1 | AF9: N | AG9: Y | AH9: N | AI9: N | AM9: 0 | AR9: N
A10: NAOMI_CA | B10: F032 | C10: 591.06928.0067 | D10: 965-23687-0023-004 | E10: NVIDIA A100 GPU BB TRAY W/8 80GB GPUS V4 | F10: A | I10: NVIDIA | L10: S03 | P10: 0 | W10: RET | AA10: N | AB10: N | AC10: N | AD10: N | AE10: 1 | AF10: N | AG10: Y | AH10: N | AI10: N | AM10: 0 | AR10: N
A11: NAOMI_CA | B11: F032 | C11: 5CS.06J54.0025 | D11: 692-2G506-0200-000 | E11: NV A100 40G PG506 DUMMY | F11: A | I11: NVIDIA | L11: B02 | P11: 0 | W11: RET | AA11: N | AB11: N | AC11: N | AD11: N | AE11: 1 | AF11: N | AG11: Y | AH11: N | AI11: N | AM11: 0 | AR11: N
A12: NAOMI_CA | B12: F032 | C12: 675-24287-0011-000 | D12: 675-24287-0011-000 | E12: ASSY VULCAN GPU BB SXM5 GH100 HMC HYBRID | F12: A | I12: NVIDIA | L12: S03 | P12: 0 | W12: RET | AA12: N | AB12: N | AC12: N | AD12: N | AE12: 1 | AF12: N | AG12: Y | AH12: N | AI12: N | AM12: 0 | AR12: N
A13: NAOMI_CA | B13: F032 | C13: 675-24287-00A0-005 | D13: 675-24287-00A0-005 | E13: HGX H800 8 GPU, SXM5 80GB HBM3 AC | F13: A | I13: NVIDIA | L13: S03 | P13: 0 | W13: RET | AA13: N | AB13: N | AC13: N | AD13: N | AE13: 1 | AF13: N | AG13: Y | AH13: N | AI13: N | AM13: 0 | AR13: N
... A28: NAOMI_CA | B28: F032 | C28: 935-24287-A800-000 | D28: 935-24287-A800-000 | E28: HGX H100 8 GPU, SXM5 80GB HBM3 AC, AWS | F28: A | I28: NVIDIA | L28: BG | P28: 0 | W28: RET | AA28: N | AB28: N | AC28: N | AD28: N | AE28: 1 | AF28: N | AG28: Y | AH28: N | AI28: N | AM28: 0 | AR28: N
A29: NAOMI_CA | B29: F032 | C29: 001.00SKL.0011 | E29: IC CPU SKL GOLD 8186 2.7GHZ 33M FC-LGA14 | F29: A | I29: NVIDIA | L29: C09 | P29: 0 | W29: RET | AA29: N | AB29: N | AC29: N | AD29: N | AE29: 1 | AF29: N | AG29: Y | AH29: N | AI29: N | AM29: 0 | AR29: N
A30: NAOMI_CA | B30: F032 | C30: 001.0ROME.M001 | E30: IC CPU AMD ROME SP3 64C 3.4G 225W LGA B0 | F30: A | I30: NVIDIA | L30: C09 | P30: 0 | W30: RET | AA30: N | AB30: N | AC30: N | AD30: N | AE30: 1 | AF30: N | AG30: Y | AH30: N | AI30: N | AM30: 0 | AR30: N
A31: NAOMI_CA | B31: F032 | C31: 012-0137-000 | D31: 012-0137-000 | E31: IC SPDT SWITCH TS5A3159DBVR SOT-23 6P | F31: A | I31: NVIDIA | L31: M01 | P31: 0 | W31: RET | AA31: N | AB31: N | AC31: N | AD31: N | AE31: 1 | AF31: N | AG31: Y | AH31: N | AI31: N | AM31: 0 | AR31: N
A32: NAOMI_CA | B32: F032 | C32: 019.20013.M008 | E32: DC DC 600W 40-60VI/11.8VO Q54SH12050NKPH | F32: A | I32: NVIDIA | L32: B02 | P32: 0 | W32: RET | AA32: N | AB32: N | AC32: N | AD32: N | AE32: 1 | AF32: N | AG32: Y | AH32: N | AI32: N | AM32: 0 | AR32: N
A33: NAOMI_CA | B33: F032 | C33: 019.20013.M010 | E33: DC/DC 700W 54VIN/12VOUT Q54SH12060RKDH | F33: A | I33: NVIDIA | L33: B02 | P33: 0 | W33: RET | AA33: N | AB33: N | AC33: N | AD33: N | AE33: 1 | AF33: N | AG33: Y | AH33: N | AI33: N | AM33: 0 | AR33: N
A34: NAOMI_CA | B34: F032 | C34: 019.20037.M001 | E34: DC/DC 9.5~15VIN/38~60VIN U50SU4P162PMAR | F34: A | I34: NVIDIA | L34: B02 | P34: 0 | W34: RET | AA34: N | AB34: N | AC34: N | AD34: N | AE34: 1 | AF34: N | AG34: Y | AH34: N | AI34: N | AM34: 0 | AR34: N
A35: NAOMI_CA | B35: F032 | C35: 020.20179.0015 | E35: CONN D-SUB FML DIP 15P DZ11437-A7261-4F | F35: A | I35: NVIDIA | L35: M01 | P35: 0 | W35: RET | AA35: N | AB35: N | AC35: N | AD35: N | AE35: 1 | AF35: N | AG35: Y | AH35: N | AI35: N | AM35: 0 | AR35: N
A36: NAOMI_CA | B36: F032 | C36: 020.20201.0015 | E36: CONN D-SUB DIP 15P DZ14427-H7156-4F | F36: A | I36: NVIDIA | L36: M01 | P36: 0 | W36: RET | AA36: N | AB36: N | AC36: N | AD36: N | AE36: 1 | AF36: N | AG36: Y | AH36: N | AI36: N | AM36: 0 | AR36: N
A37: NAOMI_CA | B37: F032 | C37: 020.50346.0164 | E37: CONN PCIE DIP 164P AAA-PCI-167-K45 | F37: A | I37: NVIDIA | L37: M01 | P37: 0 | W37: RET | AA37: N | AB37: N | AC37: N | AD37: N | AE37: 1 | AF37: N | AG37: Y | AH37: N | AI37: N | AM37: 0 | AR37: N
A38: NAOMI_CA | B38: F032 | C38: 020.50348.0164 | E38: CONN PCIE DIP 164P 2EG08223-D3D0-DH | F38: A | I38: NVIDIA | L38: M01 | P38: 0 | W38: RET | AA38: N | AB38: N | AC38: N | AD38: N | AE38: 1 | AF38: N | AG38: Y | AH38: N | AI38: N | AM38: 0 | AR38: N
A39: NAOMI_CA | B39: F032 | C39: 020.50349.0164 | E39: CONN PCIE DIP 164P 2EGE8223-D3A0-4H | F39: A | I39: NVIDIA | L39: M01 | P39: 0 | W39: RET | AA39: N | AB39: N | AC39: N | AD39: N | AE39: 1 | AF39: N | AG39: Y | AH39: N | AI39: N | AM39: 0 | AR39: N
A40: NAOMI_CA | B40: F032 | C40: 020.50350.0164 | E40: CONN PCIE DIP 164P 2EGE8223-D3D0-4H | F40: A | I40: NVIDIA | L40: M01 | P40: 0 | W40: RET | AA40: N | AB40: N | AC40: N | AD40: N | AE40: 1 | AF40: N | AG40: Y | AH40: N | AI40: N | AM40: 0 | AR40: N
A41: NAOMI_CA | B41: F032 | C41: 020.50373.0060 | E41: CONN EDGE PRESS FIT P36+S24 2ES9303-B80C | F41: A | I41: NVIDIA | L41: M01 | P41: 0 | W41: RET | AA41: N | AB41: N | AC41: N | AD41: N | AE41: 1 | AF41: N | AG41: Y | AH41: N | AI41: N | AM41: 0 | AR41: N
A42: NAOMI_CA | B42: F032 | C42: 020.50374.0050 | E42: CONN PWR EDGE DIP 50P 2ES1253-B83N4-JF | F42: A | I42: NVIDIA | L42: M01 | P42: 0 | W42: RET | AA42: N | AB42: N | AC42: N | AD42: N | AE42: 1 | AF42: N | AG42: Y | AH42: N | AI42: N | AM42: 0 | AR42: N
A43: NAOMI_CA | B43: F032 | C43: 020.50391.0064 | E43: CONN PCIE DIP 64P ST AAA-PCI-159-K34 | F43: A | I43: NVIDIA | L43: M01 | P43: 0 | W43: RET | AA43: N | AB43: N | AC43: N | AD43: N | AE43: 1 | AF43: N | AG43: Y | AH43: N | AI43: N | AM43: 0 | AR43: N
... A108: NAOMI_CA | B108: F032 | C108: 025.60025.0001 | E108: JUMPER 2P 201-H71-01GB00 | F108: A | I108: NVIDIA | L108: M01 | P108: 0 | W108: RET | AA108: N | AB108: N | AC108: N | AD108: N | AE108: 1 | AF108: N | AG108: Y | AH108: N | AI108: N | AM108: 0 | AR108: N
A109: NAOMI_CA | B109: F032 | C109: 025-0001-000 | D109: 025-0001-000 | E109: BTY RTC CR2032L/BE 225MAH PANASONIC | F109: A | I109: NVIDIA | L109: B01 | P109: 0 | W109: RET | AA109: N | AB109: N | AC109: N | AD109: N | AE109: 1 | AF109: N | AG109: Y | AH109: N | AI109: N | AM109: 0 | AR109: N
A110: NAOMI_CA | B110: F032 | C110: 027.00005.0031 | E110: POWER CABLE C19 TO C20 GW-907556 | F110: A | I110: NVIDIA | L110: C01 | P110: 0 | W110: RET | AA110: N | AB110: N | AC110: N | AD110: N | AE110: 1 | AF110: N | AG110: Y | AH110: N | AI110: N | AM110: 0 | AR110: N
A111: NAOMI_CA | B111: F032 | C111: 027.00009.0001 | E111: PWR CORD L11 AC POWER CODE LS-20+LS-19 | F111: A | I111: NVIDIA | L111: C01 | P111: 0 | W111: RET | AA111: N | AB111: N | AC111: N | AD111: N | AE111: 1 | AF111: N | AG111: Y | AH111: N | AI111: N | AM111: 0 | AR111: N
A112: NAOMI_CA | B112: F032 | C112: 027.00013.0001 | E112: CORD IEC S-LOCK C20)C19,12AWG SJT 4FTBLA | F112: A | I112: NVIDIA | L112: C01 | P112: 0 | W112: RET | AA112: N | AB112: N | AC112: N | AD112: N | AE112: 1 | AF112: N | AG112: Y | AH112: N | AI112: N | AM112: 0 | AR112: N
A113: NAOMI_CA | B113: F032 | C113: 027.00013.0011 | E113: POWER CORD IEC D-LOCK C20)C19,20A/250V | F113: A | I113: NVIDIA | L113: C01 | P113: 0 | W113: RET | AA113: N | AB113: N | AC113: N | AD113: N | AE113: 1 | AF113: N | AG113: Y | AH113: N | AI113: N | AM113: 0 | AR113: N
A114: NAOMI_CA | B114: F032 | C114: 027.00013.0021 | E114: CORD IEC D-LOOCK C20 TO C19 16A/250V BL | F114: A | I114: NVIDIA | L114: C01 | P114: 0 | W114: RET | AA114: N | AB114: N | AC114: N | AD114: N | AE114: 1 | AF114: N | AG114: Y | AH114: N | AI114: N | AM114: 0 | AR114: N
A115: NAOMI_CA | B115: F032 | C115: 030-1234-000 | D115: 030-1234-000 | E115: CABLE L80V-CABLE RADSOK | F115: A | I115: NVIDIA | L115: C01 | P115: 0 | W115: RET | AA115: N | AB115: N | AC115: N | AD115: N | AE115: 1 | AF115: N | AG115: Y | AH115: N | AI115: N | AM115: 0 | AR115: N
A116: NAOMI_CA | B116: F032 | C116: 030-1235-000 | D116: 030-1235-000 | E116: CABLE L80V-L6 PCB (PCB TO GPU) | F116: A | I116: NVIDIA | L116: C01 | P116: 0 | W116: RET | AA116: N | AB116: N | AC116: N | AD116: N | AE116: 1 | AF116: N | AG116: Y | AH116: N | AI116: N | AM116: 0 | AR116: N
